<?xml version="1.0"?>
<robot xmlns:xacro="http://ros.org/wiki/xacro">
  <xacro:include filename="$(find abb_resources)/urdf/common_materials.xacro"/>

  <xacro:macro name="abb_irb6640_185_280" params="prefix">
    <!-- link list -->
    <link name="${prefix}base_link">
      <inertial>
        <mass value="13.7742"/>
        <origin xyz="-0.028986 0.000596 0.11273"/>
        <inertia ixx="0.101998" ixy="0.000495482" ixz="0.000311158" iyy="0.13969" iyz="-0.000245375" izz="0.130433"/>
      </inertial>
      <collision name="collision">
        <geometry>
          <mesh filename="package://abb_irb6640_support/meshes/irb6640_185_280/collision/base_link.stl"/>
        </geometry>
      </collision>
      <visual name="visual">
        <geometry>
          <mesh filename="package://abb_irb6640_support/meshes/irb6640_185_280/visual/base_link.dae"/>
        </geometry>
        <material name="yellow">
          <color rgba="1 1 0 1"/>
        </material>
      </visual>
    </link>
    <link name="${prefix}link_1">
      <inertial>
        <mass value="11.8419"/>
        <origin xyz="0.000877 -0.000631 -0.062883"/>
        <inertia ixx="0.11194" ixy="-4.54988e-05" ixz="0.000280961" iyy="0.0915159" iyz="-0.000109905" izz="0.0876456"/>
      </inertial>
      <collision name="collision">
        <geometry>
          <mesh filename="package://abb_irb6640_support/meshes/irb6640_185_280/collision/link_1.stl"/>
        </geometry>
      </collision>
      <visual name="visual">
        <geometry>
          <mesh filename="package://abb_irb6640_support/meshes/irb6640_185_280/visual/link_1.dae"/>
        </geometry>
        <material name="yellow"/>
      </visual>
    </link>
    <link name="${prefix}link_2">
      <inertial>
        <mass value="17.5394"/>
        <origin xyz="-0.000928 -0.000497 0.250051"/>
        <inertia ixx="0.493558" ixy="1.32136e-05" ixz="0.000209024" iyy="0.462939" iyz="-0.00179901" izz="0.0894214"/>
      </inertial>
      <collision name="collision">
        <geometry>
          <mesh filename="package://abb_irb6640_support/meshes/irb6640_185_280/collision/link_2.stl"/>
        </geometry>
      </collision>
      <visual name="visual">
        <geometry>
          <mesh filename="package://abb_irb6640_support/meshes/irb6640_185_280/visual/link_2.dae"/>
        </geometry>
        <material name="yellow"/>
      </visual>
    </link>
    <link name="${prefix}link_3">
      <inertial>
        <mass value="7.46365"/>
        <origin xyz="0.099588 0.001143 0.032333"/>
        <inertia ixx="0.0252424" ixy="0.000142737" ixz="-0.00565542" iyy="0.0906438" iyz="0.000142213" izz="0.0825079"/>
      </inertial>
      <collision name="collision">
        <geometry>
          <mesh filename="package://abb_irb6640_support/meshes/irb6640_185_280/collision/link_3.stl"/>
        </geometry>
      </collision>
      <visual name="visual">
        <geometry>
          <mesh filename="package://abb_irb6640_support/meshes/irb6640_185_280/visual/link_3.dae"/>
        </geometry>
        <material name="yellow"/>
      </visual>
    </link>
    <link name="${prefix}link_4">
      <inertial>
        <mass value="2.74436"/>
        <origin xyz="0.381678 0.001261 0.005168"/>
        <inertia ixx="0.00573099" ixy="-0.000131119" ixz="0.000380232" iyy="0.0118352" iyz="-2.26565e-05" izz="0.0114428"/>
      </inertial>
      <collision name="collision">
        <geometry>
          <mesh filename="package://abb_irb6640_support/meshes/irb6640_185_280/collision/link_4.stl"/>
        </geometry>
      </collision>
      <visual name="visual">
        <geometry>
          <mesh filename="package://abb_irb6640_support/meshes/irb6640_185_280/visual/link_4.dae"/>
        </geometry>
        <material name="yellow"/>
      </visual>
    </link>
    <link name="${prefix}link_5">
      <inertial>
        <mass value="0.62953"/>
        <origin xyz="0.011197 -0.001056 0.000109"/>
        <inertia ixx="0.000502815" ixy="-1.03173e-05" ixz="-8.74347e-08" iyy="0.00108856" iyz="2.07657e-07" izz="0.000918873"/>
      </inertial>
      <collision name="collision">
        <geometry>
          <mesh filename="package://abb_irb6640_support/meshes/irb6640_185_280/collision/link_5.stl"/>
        </geometry>
      </collision>
      <visual name="visual">
        <geometry>
          <mesh filename="package://abb_irb6640_support/meshes/irb6640_185_280/visual/link_5.dae"/>
        </geometry>
        <material name="yellow"/>
      </visual>
    </link>
    <link name="${prefix}link_6">
      <inertial>
        <mass value="0.137"/>
        <origin xyz="-0.00706 -0.00017 -1.32E-06" rpy="0 0 0"/>
        <inertia ixx="0.001" ixy="0" ixz="0" iyy="0.001" iyz="0" izz="0.001"/>
      </inertial>
      <collision name="collision">
        <geometry>
          <mesh filename="package://abb_irb6640_support/meshes/irb6640_185_280/collision/link_6.stl"/>
        </geometry>
      </collision>
      <visual name="visual">
        <geometry>
          <mesh filename="package://abb_irb6640_support/meshes/irb6640_185_280/visual/link_6.dae"/>
        </geometry>
        <material name="yellow"/>
      </visual>
    </link>
    <link name="${prefix}tool0"/>
    <!--Cylinder and piston DLV Inercia añadida -->
    <link name="${prefix}link_cylinder">
      <collision name="collision">
        <geometry>
          <mesh filename="package://abb_irb6640_support/meshes/irb6640_185_280/collision/cylinder_link.stl"/>
        </geometry>
      </collision>
      <!--<inertial>
        <mass value="0.62953"/>
        <origin xyz="0.011197 -0.001056 0.000109"/>
        <inertia ixx="0.000502815" ixy="-1.03173e-05" ixz="-8.74347e-08" iyy="0.00108856" iyz="2.07657e-07" izz="0.000918873"/>
      </inertial>-->
      <visual name="visual">
        <geometry>
          <mesh filename="package://abb_irb6640_support/meshes/irb6640_185_280/visual/cylinder_link.dae"/>
        </geometry>
        <material name="yellow"/>
      </visual>
    </link>
    <link name="${prefix}link_piston">
      <collision name="collision">
        <geometry>
          <mesh filename="package://abb_irb6640_support/meshes/irb6640_185_280/collision/piston_link.stl"/>
        </geometry>
      </collision>
      <!--<inertial>
        <mass value="0.62953"/>
        <origin xyz="0.011197 -0.001056 0.000109"/>
        <inertia ixx="0.000502815" ixy="-1.03173e-05" ixz="-8.74347e-08" iyy="0.00108856" iyz="2.07657e-07" izz="0.000918873"/>
      </inertial>-->
      <visual name="visual">
        <geometry>
          <mesh filename="package://abb_irb6640_support/meshes/irb6640_185_280/visual/piston_link.dae"/>
        </geometry>
        <material name="yellow"/>
      </visual>
    </link>
    <!-- end of link list -->
    <!-- joint list -->
    <joint type="revolute" name="${prefix}joint_1">
      <origin xyz="0 0 0.780" rpy="0 0 0"/>
      <axis xyz="0 0 1"/>
      <parent link="${prefix}base_link"/>
      <child link="${prefix}link_1"/>
      <limit effort="0" lower="-2.967" upper="2.967" velocity="1.7453"/>
      <dynamics damping="50.0" friction="1.0"/>
      <inertial>
        <mass value="11.8419"/>
        <origin xyz="0.000877 -0.000631 -0.062883"/>
        <inertia ixx="0.11194" ixy="-4.54988e-05" ixz="0.000280961" iyy="0.0915159" iyz="-0.000109905" izz="0.0876456"/>
      </inertial>
    </joint>
    <joint type="revolute" name="${prefix}joint_2">
      <origin xyz="0.320 0 0" rpy="0 0 0"/>
      <axis xyz="0 1 0"/>
      <parent link="${prefix}link_1"/>
      <child link="${prefix}link_2"/>
      <limit effort="0" lower="-1.134" upper="1.4855" velocity="1.5707"/>
      <inertial>
        <mass value="17.5394"/>
        <origin xyz="-0.000928 -0.000497 0.250051"/>
        <inertia ixx="0.493558" ixy="1.32136e-05" ixz="0.000209024" iyy="0.462939" iyz="-0.00179901" izz="0.0894214"/>
      </inertial>
      <dynamics damping="50.0" friction="1.0"/>
    </joint>
    <joint type="revolute" name="${prefix}joint_3">
      <origin xyz="0 0 1.075" rpy="0 0 0"/>
      <axis xyz="0 1 0"/>
      <parent link="${prefix}link_2"/>
      <child link="${prefix}link_3"/>
      <limit effort="0" lower="-3.142" upper="1.222" velocity="1.5707"/>
      <inertial>
        <mass value="7.46365"/>
        <origin xyz="0.099588 0.001143 0.032333"/>
        <inertia ixx="0.0252424" ixy="0.000142737" ixz="-0.00565542" iyy="0.0906438" iyz="0.000142213" izz="0.0825079"/>
      </inertial>
      <dynamics damping="10.0" friction="1.0"/>
    </joint>
    <joint type="revolute" name="${prefix}joint_4">
      <origin xyz="0 0 0.2" rpy="0 0 0"/>
      <axis xyz="1 0 0"/>
      <parent link="${prefix}link_3"/>
      <child link="${prefix}link_4"/>
      <limit effort="0" lower="-5.236" upper="5.236" velocity="2.9671"/>
      <inertial>
        <mass value="2.74436"/>
        <origin xyz="0.381678 0.001261 0.005168"/>
        <inertia ixx="0.00573099" ixy="-0.000131119" ixz="0.000380232" iyy="0.0118352" iyz="-2.26565e-05" izz="0.0114428"/>
      </inertial>
      <dynamics damping="5.0" friction="1.0"/>
    </joint>
    <joint type="revolute" name="${prefix}joint_5">
      <origin xyz="1.392 0 0 " rpy="0 0 0"/>
      <axis xyz="0 1 0"/>
      <parent link="${prefix}link_4"/>
      <child link="${prefix}link_5"/>
      <limit effort="0" lower="-2.094" upper="2.094" velocity="2.4435"/>
      <inertial>
        <mass value="0.62953"/>
        <origin xyz="0.011197 -0.001056 0.000109"/>
        <inertia ixx="0.000502815" ixy="-1.03173e-05" ixz="-8.74347e-08" iyy="0.00108856" iyz="2.07657e-07" izz="0.000918873"/>
      </inertial>
      <dynamics damping="2.0" friction="1.0"/>
    </joint>
    <joint type="revolute" name="${prefix}joint_6">
      <origin xyz="0.2 0 0 " rpy="0 0 0"/>
      <axis xyz="1 0 0"/>
      <parent link="${prefix}link_5"/>
      <child link="${prefix}link_6"/>
      <limit effort="0" lower="-6.283" upper="6.283" velocity="3.3161"/>
      <inertial>
        <mass value="0.137"/>
        <origin xyz="-0.00706 -0.00017 -1.32E-06" rpy="0 0 0"/>
        <inertia ixx="0.001" ixy="0" ixz="0" iyy="0.001" iyz="0" izz="0.001"/>
      </inertial>
      <dynamics damping="1.0" friction="1.0"/>
    </joint>
    <!-- end of joint list -->

    <!-- ROS-Industrial 'base' frame: base_link to ABB World Coordinates transform -->
    <joint type="fixed" name="${prefix}joint_6-tool0">
      <parent link="${prefix}link_6"/>
      <child link="${prefix}tool0"/>
      <origin xyz="0 0 0" rpy="0 1.57079632679 0"/>
    </joint>
    <joint type="continuous" name="${prefix}joint_cylinder">
      <origin xyz="-0.3647 0 -0.1455" rpy="0 0 0"/>
      <axis xyz="0 1 0"/>
      <parent link="${prefix}link_1"/>
      <child link="${prefix}link_cylinder"/>
      <mimic joint="${prefix}joint_2" multiplier="-0.25"/>
    </joint>
    <joint type="continuous" name="${prefix}joint_piston">
      <origin xyz="-0.22 0 -0.0672" rpy="0 0 0"/>
      <axis xyz="0 1 0"/>
      <parent link="${prefix}link_2"/>
      <child link="${prefix}link_piston"/>
      <mimic joint="${prefix}joint_2" multiplier="-1.25"/>
    </joint>
    <!-- end of joint list -->
    <!--Camera
    <xacro:property name="camera_size" value="0.5"/>
    <xacro:property name="camera_origin_x" value="2"/>
    <xacro:property name="camera_origin_y" value="0"/>
    <xacro:property name="camera_origin_z" value="0"/>
    <link name="camera">
      <visual>
        <geometry>
          <box size="${camera_size} ${camera_size} ${camera_size}"/>
        </geometry>
        <material name="blue"/>
      </visual>
      <collision>
        <geometry>
          <box size="${camera_size} ${camera_size} ${camera_size}"/>
        </geometry>
      </collision>
    </link>

    <joint name="camera_joint" type="fixed">
      <axis xyz="0 1 0" />
      <origin xyz="${camera_origin_x} ${camera_origin_y} ${camera_origin_z}" rpy="0 0 0"/>
      <parent link="world"/>
      <child link="camera_link"/>
    </joint>-->
    <!-- ROS base_link to ABB World Coordinates transform -->
    <link name="${prefix}base" />
    <joint name="${prefix}base_link-base" type="fixed">
      <origin xyz="0 0 0" rpy="0 0 0"/>
      <parent link="${prefix}base_link"/>
      <child link="${prefix}base"/>
    </joint>
  </xacro:macro>
</robot>
